Workbook

Sheet Data
A1: Column1 | B1: Provinsi | C1: 2021 | D1: 2022 | E1: 2023 | F1: 2024 | G1: 2025
A2: 38 Provinsi | C2: Produksi Daging Sapi menurut Provinsi (Ton)
C3: 2021 | D3: 2022 | E3: 2023 | F3: 2024 | G3: 2025
A4: 1 | B4: ACEH | C4: 11674.1 | D4: 12014.96 | E4: 15644.5 | F4: 13798.92 | G4: 16681.09
A5: 2 | B5: SUMATERA UTARA | C5: 13745.06 | D5: 13859.09 | E5: 15902.8 | F5: 16857.01 | G5: 22385.29
A6: 3 | B6: SUMATERA BARAT | C6: 21375.13 | D6: 21514.66 | E6: 31194.4 | F6: 19933.05 | G6: 20633.31
A7: 4 | B7: RIAU | C7: 8948.7 | D7: 9127.69 | E7: 10974.8 | F7: 12153.85 | G7: 12854.15
A8: 5 | B8: JAMBI | C8: 4638.46 | D8: 5760.1 | E8: 4920.9 | F8: 3698.01 | G8: 4271.78
A9: 6 | B9: SUMATERA SELATAN | C9: 13832.62 | D9: 15458.87 | E9: 12171.5 | F9: 13973.6 | G9: 13144.45
A10: 7 | B10: BENGKULU | C10: 4348.01 | D10: 3329.27 | E10: 3355.5 | F10: 2779.88 | G10: 2528.89
A11: 8 | B11: LAMPUNG | C11: 21130.03 | D11: 21176.2 | E11: 22895.2 | F11: 18595.19 | G11: 18398.54
A12: 9 | B12: KEP. BANGKA BELITUNG | C12: 3233.04 | D12: 3395.04 | E12: 3485.7 | F12: 2811.03 | G12: 3244.07
A13: 10 | B13: KEP. RIAU | C13: 1453.07 | D13: 1390.39 | E13: 1820.9 | F13: 1815.6 | G13: 1103.66
A14: 11 | B14: DKI JAKARTA | C14: 16381.81 | D14: 17617.61 | E14: 17664.8 | F14: 11409.78 | G14: 16360.02
A15: 12 | B15: JAWA BARAT | C15: 78134.54 | D15: 84960.62 | E15: 76287.2 | F15: 74762.09 | G15: 80333.7
... A36: 33 | B36: PAPUA BARAT | C36: 1832.35 | D36: 1506.02 | E36: 379.6 | F36: 363.95 | G36: 304.47
A37: 34 | B37: PAPUA BARAT DAYA | C37: - | D37: - | E37: 682.6 | F37: 444.82 | G37: 463.87
A38: 35 | B38: PAPUA | C38: 2430.88 | D38: 2616.77 | E38: 1150.9 | F38: 790.17 | G38: 696.72
A39: 36 | B39: PAPUA SELATAN | C39: - | D39: - | E39: 721.6 | F39: 473.16 | G39: 634.98
A40: 37 | B40: PAPUA TENGAH | C40: - | D40: - | E40: 710.8 | F40: 855.41 | G40: 848.42
A41: 38 | B41: PAPUA PEGUNUNGAN | C41: - | D41: - | E41: 214.4 | F41: 492.05 | G41: 798.23
A42: 39 | B42: INDONESIA | C42: 487802.21 | D42: 498923.14 | E42: 503506.8 | F42: 470209.73 | G42: 499149.96

Sheet Tabel-bantuan
A1: Produksi Daging Sapi menurut Provinsi (Ton)
A3: Provinsi dengan kontribusi terbesar | D3: {=INDEX('Tabel-bantuan'!A5:E5,MATCH(MODE(MATCH('Tabel-bantuan'!A5:E5,'Tabel-bantuan'!A5:E5,0)),MATCH('Tabel-bantuan'!A5:E5,'Tabel-bantuan'!A5:E5,0),0))} -> JAWA TIMUR
A4: 2021 | B4: 2022 | C4: 2023 | D4: 2024 | E4: 2025
A5: =INDEX(Data!B3:B41, MATCH(MAX(Data!C3:C41), Data!C3:C41, 0)) -> JAWA TIMUR | B5: =INDEX(Data!B3:B41, MATCH(MAX(Data!D3:D41), Data!D3:D41, 0)) -> JAWA TIMUR | C5: =INDEX(Data!B3:B41, MATCH(MAX(Data!E3:E41), Data!E3:E41, 0)) -> JAWA TIMUR | D5: =INDEX(Data!B3:B41, MATCH(MAX(Data!F3:F41), Data!F3:F41, 0)) -> JAWA TIMUR | E5: =INDEX(Data!B3:B41, MATCH(MAX(Data!G3:G41), Data!G3:G41, 0)) -> JAWA TIMUR
A7: Indeks | B7: 7 | D7: Jumlah Pulau | E7: =COUNTIF(O53:O90,B9) -> 10 | H7: Kedudukan Produksi Skala Provinsi | I7: Persentase Andil Produksi Skala Provinsi
A8: Provinsi (Indonesia) | B8: =VLOOKUP('Tabel-bantuan'!B7,Data!$A$4:$B$41,2,FALSE) -> BENGKULU | D8: Total Produksi (Provinsi) | E8: =VLOOKUP(B8,A53:H90,8,FALSE) -> 16341.55 | H8: =COUNTIFS(O53:O90,B9,H53:H90,">" & E8) + 1 -> 8 | I8: Total Produksi Provinsi | J8: =E8 -> 16341.55
A9: Pulau | B9: =VLOOKUP($B$8,$A$53:$O$90,15,FALSE) -> SUMATERA | D9: Total Produksi (Pulau) | E9: =VLOOKUP(B9,A93:B98,2,FALSE) -> 531679.56 | I9: Total Produksi Provinsi Lainnya | J9: =E9-E8 -> 515338.01
A10: Grafik Tren Produksi
A11: 1 | B11: 2021 | C11: =VLOOKUP($B$8,Data!$B$4:$G$41,A11+1,FALSE) -> 4348.01
A12: 2 | B12: 2022 | C12: =VLOOKUP($B$8,Data!$B$4:$G$41,A12+1,FALSE) -> 3329.27
A13: 3 | B13: 2023 | C13: =VLOOKUP($B$8,Data!$B$4:$G$41,A13+1,FALSE) -> 3355.5
A14: 4 | B14: 2024 | C14: =VLOOKUP($B$8,Data!$B$4:$G$41,A14+1,FALSE) -> 2779.88
A15: 5 | B15: 2025 | C15: =VLOOKUP($B$8,Data!$B$4:$G$41,A15+1,FALSE) -> 2528.89
A30: Analisis kenaikan/penururan
A31: 1 | B31: 2021 | C31: =C11 -> 4348.01
A32: 2 | B32: 2022 | C32: =C12-C11 -> -1018.74
A33: 3 | B33: 2023 | C33: =C13-C12 -> 26.23
A34: 4 | B34: 2024 | C34: =C14-C13 -> -575.62
A35: 5 | B35: 2025 | C35: =C15-C14 -> -250.99
B52: 2021 | C52: 2022 | D52: 2023 | E52: 2024 | F52: 2025 | H52: Total Keseluruhan (2021-2025) | I52: Rank | K52: Kontribusi Skala Nasional | L52: Produksi Tertinggi | N52: Tahun Produksi Tertinggi | O52: Pulau
A53: ACEH | B53: 11674.1 | C53: 12014.96 | D53: 15644.5 | E53: 13798.92 | F53: 16681.09 | H53: =SUM($B53:$F53) -> 69813.57 | I53: =RANK(H53,$H$53:$H$90,0) -> 10 | K53: =(ROUNDUP(H53/(SUM($H$53:$H$90)),4))*100 & "%" -> 2,84% | L53: =MAX($B53,$C53,$D53,$E53,$F53) -> 16681.09 | N53: =INDEX($B$52:$F$52, MATCH($L53,$B53:$F53,0)) -> 2025 | O53: SUMATERA
A54: SUMATERA UTARA | B54: 13745.06 | C54: 13859.09 | D54: 15902.8 | E54: 16857.01 | F54: 22385.29 | H54: =SUM($B54:$F54) -> 82749.25 | I54: =RANK(H54,$H$53:$H$90,0) -> 7 | K54: =(ROUNDUP(H54/(SUM($H$53:$H$90)),4))*100 & "%" -> 3,37% | L54: =MAX($B54,$C54,$D54,$E54,$F54) -> 22385.29 | N54: =INDEX($B$52:$F$52, MATCH($L54,$B54:$F54,0)) -> 2025 | O54: SUMATERA
A55: SUMATERA BARAT | B55: 21375.13 | C55: 21514.66 | D55: 31194.4 | E55: 19933.05 | F55: 20633.31 | H55: =SUM($B55:$F55) -> 114650.55 | I55: =RANK(H55,$H$53:$H$90,0) -> 4 | K55: =(ROUNDUP(H55/(SUM($H$53:$H$90)),4))*100 & "%" -> 4,67% | L55: =MAX($B55,$C55,$D55,$E55,$F55) -> 31194.4 | N55: =INDEX($B$52:$F$52, MATCH($L55,$B55:$F55,0)) -> 2023 | O55: SUMATERA
A56: RIAU | B56: 8948.7 | C56: 9127.69 | D56: 10974.8 | E56: 12153.85 | F56: 12854.15 | H56: =SUM($B56:$F56) -> 54059.19 | I56: =RANK(H56,$H$53:$H$90,0) -> 13 | K56: =(ROUNDUP(H56/(SUM($H$53:$H$90)),4))*100 & "%" -> 2,2% | L56: =MAX($B56,$C56,$D56,$E56,$F56) -> 12854.15 | N56: =INDEX($B$52:$F$52, MATCH($L56,$B56:$F56,0)) -> 2025 | O56: SUMATERA
A57: JAMBI | B57: 4638.46 | C57: 5760.1 | D57: 4920.9 | E57: 3698.01 | F57: 4271.78 | H57: =SUM($B57:$F57) -> 23289.25 | I57: =RANK(H57,$H$53:$H$90,0) -> 21 | K57: =(ROUNDUP(H57/(SUM($H$53:$H$90)),4))*100 & "%" -> 0,95% | L57: =MAX($B57,$C57,$D57,$E57,$F57) -> 5760.1 | N57: =INDEX($B$52:$F$52, MATCH($L57,$B57:$F57,0)) -> 2022 | O57: SUMATERA
A58: SUMATERA SELATAN | B58: 13832.62 | C58: 15458.87 | D58: 12171.5 | E58: 13973.6 | F58: 13144.45 | H58: =SUM($B58:$F58) -> 68581.04 | I58: =RANK(H58,$H$53:$H$90,0) -> 11 | K58: =(ROUNDUP(H58/(SUM($H$53:$H$90)),4))*100 & "%" -> 2,79% | L58: =MAX($B58,$C58,$D58,$E58,$F58) -> 15458.87 | N58: =INDEX($B$52:$F$52, MATCH($L58,$B58:$F58,0)) -> 2022 | O58: SUMATERA
A59: BENGKULU | B59: 4348.01 | C59: 3329.27 | D59: 3355.5 | E59: 2779.88 | F59: 2528.89 | H59: =SUM($B59:$F59) -> 16341.55 | I59: =RANK(H59,$H$53:$H$90,0) -> 24 | K59: =(ROUNDUP(H59/(SUM($H$53:$H$90)),4))*100 & "%" -> 0,67% | L59: =MAX($B59,$C59,$D59,$E59,$F59) -> 4348.01 | N59: =INDEX($B$52:$F$52, MATCH($L59,$B59:$F59,0)) -> 2021 | O59: SUMATERA
A60: LAMPUNG | B60: 21130.03 | C60: 21176.2 | D60: 22895.2 | E60: 18595.19 | F60: 18398.54 | H60: =SUM($B60:$F60) -> 102195.16 | I60: =RANK(H60,$H$53:$H$90,0) -> 5 | K60: =(ROUNDUP(H60/(SUM($H$53:$H$90)),4))*100 & "%" -> 4,16% | L60: =MAX($B60,$C60,$D60,$E60,$F60) -> 22895.2 | N60: =INDEX($B$52:$F$52, MATCH($L60,$B60:$F60,0)) -> 2023 | O60: SUMATERA
A61: KEP. BANGKA BELITUNG | B61: 3233.04 | C61: 3395.04 | D61: 3485.7 | E61: 2811.03 | F61: 3244.07 | H61: =SUM($B61:$F61) -> 16168.88 | I61: =RANK(H61,$H$53:$H$90,0) -> 25 | K61: =(ROUNDUP(H61/(SUM($H$53:$H$90)),4))*100 & "%" -> 0,66% | L61: =MAX($B61,$C61,$D61,$E61,$F61) -> 3485.7 | N61: =INDEX($B$52:$F$52, MATCH($L61,$B61:$F61,0)) -> 2023 | O61: SUMATERA
A62: KEP. RIAU | B62: 1453.07 | C62: 1390.39 | D62: 1820.9 | E62: 1815.6 | F62: 1103.66 | H62: =SUM($B62:$F62) -> 7583.62 | I62: =RANK(H62,$H$53:$H$90,0) -> 30 | K62: =(ROUNDUP(H62/(SUM($H$53:$H$90)),4))*100 & "%" -> 0,31% | L62: =MAX($B62,$C62,$D62,$E62,$F62) -> 1820.9 | N62: =INDEX($B$52:$F$52, MATCH($L62,$B62:$F62,0)) -> 2023 | O62: SUMATERA
A63: DKI JAKARTA | B63: 16381.81 | C63: 17617.61 | D63: 17664.8 | E63: 11409.78 | F63: 16360.02 | H63: =SUM($B63:$F63) -> 79434.02 | I63: =RANK(H63,$H$53:$H$90,0) -> 8 | K63: =(ROUNDUP(H63/(SUM($H$53:$H$90)),4))*100 & "%" -> 3,23% | L63: =MAX($B63,$C63,$D63,$E63,$F63) -> 17664.8 | N63: =INDEX($B$52:$F$52, MATCH($L63,$B63:$F63,0)) -> 2023 | O63: JAWA
A64: JAWA BARAT | B64: 78134.54 | C64: 84960.62 | D64: 76287.2 | E64: 74762.09 | F64: 80333.7 | H64: =SUM($B64:$F64) -> 394478.15 | I64: =RANK(H64,$H$53:$H$90,0) -> 2 | K64: =(ROUNDUP(H64/(SUM($H$53:$H$90)),4))*100 & "%" -> 16,04% | L64: =MAX($B64,$C64,$D64,$E64,$F64) -> 84960.62 | N64: =INDEX($B$52:$F$52, MATCH($L64,$B64:$F64,0)) -> 2022 | O64: JAWA
... A85: PAPUA BARAT | B85: 1832.35 | C85: 1506.02 | D85: 379.6 | E85: 363.95 | F85: 304.47 | H85: =SUM($B85:$F85) -> 4386.39 | I85: =RANK(H85,$H$53:$H$90,0) -> 33 | K85: =(ROUNDUP(H85/(SUM($H$53:$H$90)),4))*100 & "%" -> 0,18% | L85: =MAX($B85,$C85,$D85,$E85,$F85) -> 1832.35 | N85: =INDEX($B$52:$F$52, MATCH($L85,$B85:$F85,0)) -> 2021 | O85: MALUKU & PAPUA
A86: PAPUA BARAT DAYA | B86: - | C86: - | D86: 682.6 | E86: 444.82 | F86: 463.87 | H86: =SUM($B86:$F86) -> 1591.29 | I86: =RANK(H86,$H$53:$H$90,0) -> 37 | K86: =(ROUNDUP(H86/(SUM($H$53:$H$90)),4))*100 & "%" -> 0,07% | L86: =MAX($B86,$C86,$D86,$E86,$F86) -> 682.6 | N86: =INDEX($B$52:$F$52, MATCH($L86,$B86:$F86,0)) -> 2023 | O86: MALUKU & PAPUA
A87: PAPUA | B87: 2430.88 | C87: 2616.77 | D87: 1150.9 | E87: 790.17 | F87: 696.72 | H87: =SUM($B87:$F87) -> 7685.44 | I87: =RANK(H87,$H$53:$H$90,0) -> 29 | K87: =(ROUNDUP(H87/(SUM($H$53:$H$90)),4))*100 & "%" -> 0,32% | L87: =MAX($B87,$C87,$D87,$E87,$F87) -> 2616.77 | N87: =INDEX($B$52:$F$52, MATCH($L87,$B87:$F87,0)) -> 2022 | O87: MALUKU & PAPUA
A88: PAPUA SELATAN | B88: - | C88: - | D88: 721.6 | E88: 473.16 | F88: 634.98 | H88: =SUM($B88:$F88) -> 1829.74 | I88: =RANK(H88,$H$53:$H$90,0) -> 36 | K88: =(ROUNDUP(H88/(SUM($H$53:$H$90)),4))*100 & "%" -> 0,08% | L88: =MAX($B88,$C88,$D88,$E88,$F88) -> 721.6 | N88: =INDEX($B$52:$F$52, MATCH($L88,$B88:$F88,0)) -> 2023 | O88: MALUKU & PAPUA
A89: PAPUA TENGAH | B89: - | C89: - | D89: 710.8 | E89: 855.41 | F89: 848.42 | H89: =SUM($B89:$F89) -> 2414.63 | I89: =RANK(H89,$H$53:$H$90,0) -> 35 | K89: =(ROUNDUP(H89/(SUM($H$53:$H$90)),4))*100 & "%" -> 0,1% | L89: =MAX($B89,$C89,$D89,$E89,$F89) -> 855.41 | N89: =INDEX($B$52:$F$52, MATCH($L89,$B89:$F89,0)) -> 2024 | O89: MALUKU & PAPUA
A90: PAPUA PEGUNUNGAN | B90: - | C90: - | D90: 214.4 | E90: 492.05 | F90: 798.23 | H90: =SUM($B90:$F90) -> 1504.68 | I90: =RANK(H90,$H$53:$H$90,0) -> 38 | K90: =(ROUNDUP(H90/(SUM($H$53:$H$90)),4))*100 & "%" -> 0,07% | L90: =MAX($B90,$C90,$D90,$E90,$F90) -> 798.23 | N90: =INDEX($B$52:$F$52, MATCH($L90,$B90:$F90,0)) -> 2025 | O90: MALUKU & PAPUA
A92: TOTAL PRODUKSI BERDASARKAN PULAU
A93: SUMATERA | B93: =SUM(B53:F60) -> 531679.56
...

Sheet Dashboard
B2: Dashboard Produksi Daging Sapi di Indonesia (Ton) Tahun 2021-2025
B6: Pertumbuhan Produksi Daging Sapi Nasional (Ton) Tahun 2021-2025 | H6: Jumlah Provinsi | L6: Top 10 Produksi Daging Sapi (Ton) Tahun 2021-2025
H7: =COUNTA(Data!B4:B41) -> 38
H10: Provinsi dengan Kontribusi Terbesar
H11: {=INDEX('Tabel-bantuan'!A5:E5,MATCH(MODE(MATCH('Tabel-bantuan'!A5:E5,'Tabel-bantuan'!A5:E5,0)),MATCH('Tabel-bantuan'!A5:E5,'Tabel-bantuan'!A5:E5,0),0))} -> JAWA TIMUR
H14: Total Produksi Nasional (Ton)
H15: =SUM(Data!C42:G42) -> 2459591.8
H18: Produksi Daging Sapi (Ton)
H19: Terendah
H20: =MIN(Data!$C$4:$G$41) -> 214.4
H21: Tertinggi
H22: =MAX(Data!$C$4:$G$41) -> 110991.18
B24: Sebaran Data Provinsi
M26: Persentase Andil Produksi Skala Pulau
E45: Total Produksi (Ton) Tahun 2021-2025 | H45: Kontribusi Nasional | N45: Kedudukan Produksi Skala Provinsi
E46: =VLOOKUP('Tabel-bantuan'!B8,'Tabel-bantuan'!A53:H90,8,FALSE) -> 16341.55 | H46: ="Menyumbang " & VLOOKUP('Tabel-bantuan'!B8,'Tabel-bantuan'!A53:K90,11,FALSE) & " Pasokan Nasional" -> Menyumbang 0,67% Pasokan Nasional | N46: ='Tabel-bantuan'!H8 & " dari " & 'Tabel-bantuan'!E7 & " Provinsi di Pulau " & 'Tabel-bantuan'!B9 -> 8 dari 10 Provinsi di Pulau SUMATERA
E49: Kedudukan Produksi Skala Nasional | H49: Produksi Tertinggi | N49: ='Tabel-bantuan'!B8 -> BENGKULU
E50: =VLOOKUP('Tabel-bantuan'!B8,'Tabel-bantuan'!A53:I90,9,FALSE) & " dari 38 Provinsi" -> 24 dari 38 Provinsi | H50: =VLOOKUP('Tabel-bantuan'!B8,'Tabel-bantuan'!A53:N90,12,FALSE) & " Ton" & " ( Tahun " & VLOOKUP('Tabel-bantuan'!B8,'Tabel-bantuan'!A53:N90,14,FALSE) & " )" -> 4348,01 Ton ( Tahun 2021 )
