Workbook

Sheet Data
B1: Pintu Masuk | C1: Jumlah Kunjungan Wisatawan Mancanegara per bulan ke Indonesia Menurut Pintu Masuk 2021-2025 (Kunjungan)
C3: 2021 | P3: 2022 | AC3: 2023 | AP3: 2024 | BC3: 2025
C4: Januari | D4: Februari | E4: Maret | F4: April | G4: Mei | H4: Juni | I4: Juli | J4: Agustus | K4: September | L4: Oktober | M4: November | N4: Desember | O4: Tahunan | P4: Januari | Q4: Februari | R4: Maret | S4: April | T4: Mei | U4: Juni | V4: Juli | W4: Agustus | X4: September | Y4: Oktober | Z4: November | AA4: Desember | AB4: Tahunan | AC4: Januari | AD4: Februari | AE4: Maret | AF4: April | AG4: Mei | AH4: Juni | AI4: Juli | AJ4: Agustus | AK4: September | AL4: Oktober | AM4: November | AN4: Desember | AO4: Tahunan | AP4: Januari | AQ4: Februari | AR4: Maret | AS4: April | AT4: Mei | AU4: Juni | AV4: Juli | AW4: Agustus | AX4: September | AY4: Oktober | AZ4: November | BA4: Desember | BB4: Tahunan | BC4: Januari | BD4: Februari | BE4: Maret | BF4: April | BG4: Mei | BH4: Juni | BI4: Juli | BJ4: Agustus | BK4: September | BL4: Oktober | BM4: November | BN4: Desember | BO4: Tahunan | BP4: Total
A5: A | B5: A. Pintu Udara | C5: 1731 | D5: 7110 | E5: 12852 | F5: 18326 | G5: 14040 | H5: 16234 | I5: 7175 | J5: 1609 | K5: 4748 | L5: 15722 | M5: 19909 | N5: 17786 | O5: 137242 | P5: 14555 | Q5: 17834 | R5: 39062 | S5: 97401 | T5: 183830 | U5: 280482 | V5: 387184 | W5: 422500 | X5: 424198 | Y5: 447074 | Z5: 429979 | AA5: 551927 | AB5: 3296026 | AC5: 484497 | AD5: 487449 | AE5: 554665 | AF5: 560434 | AG5: 659065 | AH5: 707476 | AI5: 819496 | AJ5: 826446 | AK5: 777537 | AL5: 707584 | AM5: 656709 | AN5: 731293 | AO5: 7972651 | AP5: 631961 | AQ5: 735072 | AR5: 682439 | AS5: 750085 | AT5: 835722 | AU5: 821654 | AV5: 994583 | AW5: 987547 | AX5: 941903 | AY5: 859747 | AZ5: 756972 | BA5: 832865 | BB5: 9830550 | BC5: 801614 | BD5: 718609 | BE5: 669479 | BF5: 854756 | BG5: 941092 | BH5: 978929 | BI5: 1101619 | BJ5: 1108133 | BK5: 996518 | BL5: 954216 | BM5: 805662 | BN5: 888664 | BO5: 10819291
A6: 1 | B6: Ngurah Rai | C6: 2 | D6: 12 | E6: 3 | F6: 9 | G6: 8 | H6: 1 | I6: 0 | J6: 0 | K6: 0 | L6: 2 | M6: 6 | N6: 0 | O6: 43 | P6: 0 | Q6: 1293 | R6: 14617 | S6: 58315 | T6: 115553 | U6: 181545 | V6: 246442 | W6: 276627 | X6: 291115 | Y6: 305152 | Z6: 287025 | AA6: 376361 | AB6: 2154045 | AC6: 329909 | AD6: 317005 | AE6: 366956 | AF6: 410281 | AG6: 439454 | AH6: 478127 | AI6: 541272 | AJ6: 522063 | AK6: 508297 | AL6: 458845 | AM6: 397522 | AN6: 478382 | AO6: 5248113 | AP6: 414937 | AQ6: 454398 | AR6: 463804 | AS6: 502870 | AT6: 544492 | AU6: 520792 | AV6: 625569 | AW6: 613540 | AX6: 591848 | AY6: 554892 | AZ6: 472714 | BA6: 548685 | BB6: 6308541 | BC6: 526831 | BD6: 444411 | BE6: 464697 | BF6: 587315 | BG6: 602055 | BH6: 637744 | BI6: 697068 | BJ6: 682839 | BK6: 634482 | BL6: 594846 | BM6: 476507 | BN6: 558790 | BO6: 6907585 | BP6: =SUM($BO6,$BB6,$AO6,$AB6,$O6) -> 20618327
A7: 2 | B7: Soekarno-Hatta | C7: 1238 | D7: 5958 | E7: 10188 | F7: 15471 | G7: 12775 | H7: 13448 | I7: 5466 | J7: 1071 | K7: 4081 | L7: 13700 | M7: 18971 | N7: 16696 | O7: 119063 | P7: 14073 | Q7: 15406 | R7: 23320 | S7: 36061 | T7: 57844 | U7: 85587 | V7: 119179 | W7: 121427 | X7: 111033 | Y7: 112527 | Z7: 113729 | AA7: 124475 | AB7: 934661 | AC7: 115101 | AD7: 124803 | AE7: 140859 | AF7: 99289 | AG7: 158550 | AH7: 161114 | AI7: 204000 | AJ7: 218512 | AK7: 190058 | AL7: 181627 | AM7: 186695 | AN7: 172397 | AO7: 1953005 | AP7: 157979 | AQ7: 187641 | AR7: 160917 | AS7: 157409 | AT7: 201574 | AU7: 225985 | AV7: 271680 | AW7: 272849 | AX7: 250852 | AY7: 218170 | AZ7: 212178 | BA7: 207019 | BB7: 2524253 | BC7: 193433 | BD7: 199306 | BE7: 146390 | BF7: 186523 | BG7: 233751 | BH7: 236013 | BI7: 290369 | BJ7: 304970 | BK7: 244404 | BL7: 254968 | BM7: 240330 | BN7: 230381 | BO7: 2760838 | BP7: =SUM($BO7,$BB7,$AO7,$AB7,$O7) -> 8291820
A8: 3 | B8: Juanda | C8: 20 | D8: 69 | E8: 52 | F8: 106 | G8: 160 | H8: 181 | I8: 52 | J8: 10 | K8: 2 | L8: 37 | M8: 0 | N8: 0 | O8: 689 | P8: 0 | Q8: 0 | R8: 57 | S8: 1468 | T8: 4598 | U8: 4722 | V8: 6087 | W8: 8386 | X8: 9152 | Y8: 9415 | Z8: 9644 | AA8: 14264 | AB8: 67793 | AC8: 10777 | AD8: 11882 | AE8: 10606 | AF8: 12361 | AG8: 15734 | AH8: 18025 | AI8: 20303 | AJ8: 25548 | AK8: 25593 | AL8: 21996 | AM8: 22389 | AN8: 23244 | AO8: 218458 | AP8: 17196 | AQ8: 28026 | AR8: 18543 | AS8: 29043 | AT8: 31222 | AU8: 25015 | AV8: 34446 | AW8: 38587 | AX8: 31700 | AY8: 28182 | AZ8: 20820 | BA8: 19265 | BB8: 322045 | BC8: 22119 | BD8: 19205 | BE8: 15647 | BF8: 24800 | BG8: 33409 | BH8: 34092 | BI8: 34421 | BJ8: 37406 | BK8: 32664 | BL8: 29534 | BM8: 21629 | BN8: 25019 | BO8: 329945 | BP8: =SUM($BO8,$BB8,$AO8,$AB8,$O8) -> 938930
A9: 4 | B9: Kualanamu | C9: 11 | D9: 17 | E9: 45 | F9: 22 | G9: 50 | H9: 38 | I9: 28 | J9: 4 | K9: 3 | L9: 0 | M9: 0 | N9: 0 | O9: 218 | P9: 0 | Q9: 0 | R9: 11 | S9: 494 | T9: 3861 | U9: 5165 | V9: 7518 | W9: 10287 | X9: 5895 | Y9: 11454 | Z9: 10615 | AA9: 19198 | AB9: 74498 | AC9: 14146 | AD9: 15072 | AE9: 16106 | AF9: 15497 | AG9: 16262 | AH9: 16527 | AI9: 17478 | AJ9: 20843 | AK9: 15783 | AL9: 14161 | AM9: 16363 | AN9: 18237 | AO9: 196475 | AP9: 14751 | AQ9: 24628 | AR9: 15068 | AS9: 25178 | AT9: 20469 | AU9: 16949 | AV9: 22693 | AW9: 21930 | AX9: 24956 | AY9: 20129 | AZ9: 19145 | BA9: 21142 | BB9: 247038 | BC9: 23011 | BD9: 22546 | BE9: 16881 | BF9: 19709 | BG9: 26183 | BH9: 25183 | BI9: 28306 | BJ9: 29858 | BK9: 29107 | BL9: 24621 | BM9: 20826 | BN9: 23425 | BO9: 289656 | BP9: =SUM($BO9,$BB9,$AO9,$AB9,$O9) -> 807885
A10: 5 | B10: Husein Sastranegara | C10: 0 | D10: 0 | E10: 0 | F10: 0 | G10: 1 | H10: 0 | I10: 0 | J10: 0 | K10: 0 | L10: 0 | M10: 6 | N10: 0 | O10: 7 | P10: 0 | Q10: 0 | R10: 0 | S10: 0 | T10: 0 | U10: 49 | V10: 21 | W10: 15 | X10: 0 | Y10: 0 | Z10: 0 | AA10: 0 | AB10: 85 | AC10: 0 | AD10: 0 | AE10: 0 | AF10: 0 | AG10: 17 | AH10: 24 | AI10: 3 | AJ10: 0 | AK10: 0 | AL10: 0 | AM10: 0 | AN10: 0 | AO10: 44 | AP10: 0 | AQ10: 0 | AR10: 0 | AS10: 0 | AT10: 0 | AU10: 0 | AV10: 22 | AW10: 0 | AX10: 0 | AY10: 0 | AZ10: 0 | BA10: 0 | BB10: 22 | BC10: 0 | BD10: 0 | BE10: 0 | BF10: 0 | BG10: 0 | BH10: 0 | BI10: 0 | BJ10: 0 | BK10: 0 | BL10: 0 | BM10: 0 | BN10: 0 | BO10: 0 | BP10: =SUM($BO10,$BB10,$AO10,$AB10,$O10) -> 158
A11: 6 | B11: Adi Sucipto | C11: 0 | D11: 0 | E11: 0 | F11: 0 | G11: 0 | H11: 0 | I11: 0 | J11: 0 | K11: 0 | L11: 0 | M11: 0 | N11: 0 | O11: 0 | P11: 0 | Q11: 0 | R11: 0 | S11: 35 | T11: 260 | U11: 369 | V11: 809 | W11: 640 | X11: 974 | Y11: 1933 | Z11: 1947 | AA11: 5169 | AB11: 12136 | AC11: 3878 | AD11: 4839 | AE11: 5007 | AF11: 5592 | AG11: 8160 | AH11: 11188 | AI11: 12444 | AJ11: 12974 | AK11: 11855 | AL11: 8536 | AM11: 9675 | AN11: 11338 | AO11: 105486 | AP11: 6879 | AQ11: 9813 | AR11: 6258 | AS11: 8790 | AT11: 11323 | AU11: 8134 | AV11: 11120 | AW11: 10136 | AX11: 9621 | AY11: 7828 | AZ11: 6728 | BA11: 7167 | BB11: 103797 | BC11: 6717 | BD11: 6087 | BE11: 3185 | BF11: 7135 | BG11: 9699 | BH11: 10424 | BI11: 11322 | BJ11: 12554 | BK11: 10960 | BL11: 8712 | BM11: 8005 | BN11: 8017 | BO11: 102817 | BP11: =SUM($BO11,$BB11,$AO11,$AB11,$O11) -> 324236
A12: 7 | B12: Bandara Int. Lombok | C12: 1 | D12: 0 | E12: 2 | F12: 0 | G12: 0 | H12: 0 | I12: 0 | J12: 26 | K12: 0 | L12: 0 | M12: 0 | N12: 0 | O12: 29 | P12: 0 | Q12: 488 | R12: 12 | S12: 0 | T12: 487 | U12: 1011 | V12: 1658 | W12: 2054 | X12: 2251 | Y12: 2226 | Z12: 1921 | AA12: 2914 | AB12: 15022 | AC12: 2202 | AD12: 2355 | AE12: 2099 | AF12: 2903 | AG12: 4848 | AH12: 5721 | AI12: 6433 | AJ12: 6245 | AK12: 6294 | AL12: 5904 | AM12: 5278 | AN12: 7304 | AO12: 57586 | AP12: 4958 | AQ12: 7748 | AR12: 5208 | AS12: 6536 | AT12: 7742 | AU12: 6893 | AV12: 8652 | AW12: 8122 | AX12: 7461 | AY12: 7169 | AZ12: 4947 | BA12: 6108 | BB12: 81544 | BC12: 6295 | BD12: 4926 | BE12: 5441 | BF12: 7812 | BG12: 8641 | BH12: 7784 | BI12: 10512 | BJ12: 10207 | BK12: 9333 | BL12: 9321 | BM12: 6689 | BN12: 7714 | BO12: 94675 | BP12: =SUM($BO12,$BB12,$AO12,$AB12,$O12) -> 248856
A13: 8 | B13: Sam Ratulangi | C13: 433 | D13: 1027 | E13: 2513 | F13: 2685 | G13: 1015 | H13: 2435 | I13: 695 | J13: 5 | K13: 593 | L13: 1952 | M13: 851 | N13: 1035 | O13: 15239 | P13: 466 | Q13: 647 | R13: 1045 | S13: 851 | T13: 843 | U13: 1472 | V13: 1684 | W13: 1758 | X13: 2178 | Y13: 1581 | Z13: 1721 | AA13: 1142 | AB13: 15388 | AC13: 803 | AD13: 1848 | AE13: 4793 | AF13: 4156 | AG13: 3798 | AH13: 3691 | AI13: 3782 | AJ13: 5397 | AK13: 5922 | AL13: 4645 | AM13: 4611 | AN13: 3917 | AO13: 47363 | AP13: 3384 | AQ13: 2615 | AR13: 4045 | AS13: 3451 | AT13: 3427 | AU13: 3424 | AV13: 4743 | AW13: 4436 | AX13: 4791 | AY13: 4674 | AZ13: 4532 | BA13: 4097 | BB13: 47619 | BC13: 3788 | BD13: 3497 | BE13: 4403 | BF13: 4070 | BG13: 3902 | BH13: 3742 | BI13: 5903 | BJ13: 5656 | BK13: 5600 | BL13: 6513 | BM13: 7401 | BN13: 7020 | BO13: 61495 | BP13: =SUM($BO13,$BB13,$AO13,$AB13,$O13) -> 187104
A14: 9 | B14: Minangkabau | C14: 0 | D14: 0 | E14: 0 | F14: 0 | G14: 0 | H14: 0 | I14: 0 | J14: 0 | K14: 0 | L14: 0 | M14: 0 | N14: 0 | O14: 0 | P14: 0 | Q14: 0 | R14: 0 | S14: 0 | T14: 0 | U14: 0 | V14: 0 | W14: 0 | X14: 0 | Y14: 371 | Z14: 709 | AA14: 3062 | AB14: 4142 | AC14: 2878 | AD14: 3590 | AE14: 2765 | AF14: 4100 | AG14: 4624 | AH14: 5226 | AI14: 4946 | AJ14: 5577 | AK14: 5453 | AL14: 4925 | AM14: 5898 | AN14: 6710 | AO14: 56692 | AP14: 4689 | AQ14: 8229 | AR14: 2976 | AS14: 7166 | AT14: 7107 | AU14: 4561 | AV14: 5936 | AW14: 6685 | AX14: 8232 | AY14: 7511 | AZ14: 6041 | BA14: 7550 | BB14: 76683 | BC14: 8490 | BD14: 7810 | BE14: 3649 | BF14: 6270 | BG14: 8312 | BH14: 8621 | BI14: 7674 | BJ14: 8216 | BK14: 9699 | BL14: 7588 | BM14: 6611 | BN14: 7081 | BO14: 90021 | BP14: =SUM($BO14,$BB14,$AO14,$AB14,$O14) -> 227538
A15: 10 | B15: Sultan Syarif Kasim II | C15: 1 | D15: 3 | E15: 8 | F15: 1 | G15: 0 | H15: 88 | I15: 0 | J15: 0 | K15: 0 | L15: 0 | M15: 0 | N15: 0 | O15: 101 | P15: 0 | Q15: 0 | R15: 0 | S15: 0 | T15: 0 | U15: 0 | V15: 32 | W15: 117 | X15: 272 | Y15: 632 | Z15: 955 | AA15: 1977 | AB15: 3985 | AC15: 1624 | AD15: 1914 | AE15: 1697 | AF15: 2453 | AG15: 2293 | AH15: 2447 | AI15: 2111 | AJ15: 2770 | AK15: 2166 | AL15: 2377 | AM15: 2921 | AN15: 2964 | AO15: 27737 | AP15: 2126 | AQ15: 3709 | AR15: 2081 | AS15: 3996 | AT15: 2849 | AU15: 4637 | AV15: 2516 | AW15: 3940 | AX15: 3320 | AY15: 2637 | AZ15: 2485 | BA15: 2800 | BB15: 37096 | BC15: 2684 | BD15: 2446 | BE15: 2612 | BF15: 2793 | BG15: 3277 | BH15: 3443 | BI15: 2688 | BJ15: 3201 | BK15: 3938 | BL15: 3091 | BM15: 3210 | BN15: 3775 | BO15: 37158 | BP15: =SUM($BO15,$BB15,$AO15,$AB15,$O15) -> 106077
A16: 11 | B16: Sultan Iskandar Muda | C16: 0 | D16: 0 | E16: 0 | F16: 1 | G16: 4 | H16: 3 | I16: 1 | J16: 0 | K16: 0 | L16: 0 | M16: 0 | N16: 2 | O16: 11 | P16: 0 | Q16: 0 | R16: 0 | S16: 0 | T16: 0 | U16: 0 | V16: 0 | W16: 0 | X16: 0 | Y16: 257 | Z16: 452 | AA16: 1177 | AB16: 1886 | AC16: 1440 | AD16: 2024 | AE16: 1901 | AF16: 1349 | AG16: 2350 | AH16: 2157 | AI16: 2582 | AJ16: 3108 | AK16: 2481 | AL16: 1875 | AM16: 2577 | AN16: 3461 | AO16: 27305 | AP16: 2379 | AQ16: 4421 | AR16: 1582 | AS16: 2533 | AT16: 2050 | AU16: 2080 | AV16: 2489 | AW16: 3042 | AX16: 3909 | AY16: 3237 | AZ16: 2534 | BA16: 3598 | BB16: 33854 | BC16: 3811 | BD16: 3825 | BE16: 1512 | BF16: 2184 | BG16: 4003 | BH16: 3607 | BI16: 4088 | BJ16: 4305 | BK16: 5390 | BL16: 4257 | BM16: 3627 | BN16: 4217 | BO16: 44826 | BP16: =SUM($BO16,$BB16,$AO16,$AB16,$O16) -> 107882
A17: 12 | B17: Ahmad Yani | C17: 0 | D17: 0 | E17: 2 | F17: 2 | G17: 1 | H17: 3 | I17: 0 | J17: 0 | K17: 0 | L17: 0 | M17: 0 | N17: 0 | O17: 8 | P17: 0 | Q17: 0 | R17: 0 | S17: 0 | T17: 0 | U17: 0 | V17: 0 | W17: 0 | X17: 0 | Y17: 0 | Z17: 0 | AA17: 0 | AB17: 0 | AC17: 1 | AD17: 1 | AE17: 1 | AF17: 0 | AG17: 0 | AH17: 0 | AI17: 0 | AJ17: 0 | AK17: 8 | AL17: 0 | AM17: 0 | AN17: 0 | AO17: 11 | AP17: 0 | AQ17: 2 | AR17: 0 | AS17: 0 | AT17: 0 | AU17: 0 | AV17: 0 | AW17: 0 | AX17: 0 | AY17: 0 | AZ17: 0 | BA17: 0 | BB17: 2 | BC17: 0 | BD17: 0 | BE17: 0 | BF17: 0 | BG17: 0 | BH17: 4 | BI17: 11 | BJ17: 0 | BK17: 1381 | BL17: 1618 | BM17: 1365 | BN17: 1627 | BO17: 6006 | BP17: =SUM($BO17,$BB17,$AO17,$AB17,$O17) -> 6027
... A21: 16 | B21: Pintu Udara Lainnya | C21: 25 | D21: 24 | E21: 39 | F21: 29 | G21: 26 | H21: 37 | I21: 129 | J21: 16 | K21: 69 | L21: 31 | M21: 75 | N21: 53 | O21: 553 | P21: 16 | Q21: 0 | R21: 0 | S21: 13 | T21: 20 | U21: 31 | V21: 2024 | W21: 682 | X21: 623 | Y21: 539 | Z21: 735 | AA21: 658 | AB21: 5341 | AC21: 672 | AD21: 645 | AE21: 953 | AF21: 889 | AG21: 1543 | AH21: 1341 | AI21: 2376 | AJ21: 1796 | AK21: 1840 | AL21: 1518 | AM21: 1585 | AN21: 1831 | AO21: 16989 | AP21: 1941 | AQ21: 2432 | AR21: 1376 | AS21: 1711 | AT21: 2396 | AU21: 2092 | AV21: 3170 | AW21: 2842 | AX21: 3882 | AY21: 4224 | AZ21: 3901 | BA21: 4347 | BB21: 34314 | BC21: 3231 | BD21: 3571 | BE21: 3758 | BF21: 5317 | BG21: 6381 | BH21: 6311 | BI21: 7243 | BJ21: 5969 | BK21: 5195 | BL21: 5074 | BM21: 5353 | BN21: 6069 | BO21: 63472 | BP21: =SUM($BO21,$BB21,$AO21,$AB21,$O21) -> 120669
A22: B | B22: B. Pintu Laut | C22: 37667 | D22: 29300 | E22: 35317 | F22: 30918 | G22: 39720 | H22: 29929 | I22: 35511 | J22: 33497 | K22: 33397 | L22: 38245 | M22: 32741 | N22: 39230 | O22: 415472 | P22: 58442 | Q22: 51539 | R22: 60357 | S22: 69085 | T22: 105719 | U22: 134664 | V22: 184193 | W22: 164918 | X22: 196668 | Y22: 207390 | Z22: 193894 | AA22: 299967 | AB22: 1726836 | AC22: 224851 | AD22: 191063 | AE22: 236181 | AF22: 235660 | AG22: 214326 | AH22: 276039 | AI22: 225106 | AJ22: 220199 | AK22: 212770 | AL22: 186161 | AM22: 190258 | AN22: 291763 | AO22: 2704377 | AP22: 198072 | AQ22: 239718 | AR22: 252013 | AS22: 211716 | AT22: 212718 | AU22: 261165 | AV22: 212433 | AW22: 248758 | AX22: 231748 | AY22: 218620 | AZ22: 223293 | BA22: 264692 | BB22: 2774905 | BC22: 232267 | BD22: 203450 | BE22: 206397 | BF22: 200550 | BG22: 244169 | BH22: 307815 | BI22: 242599 | BJ22: 263040 | BK22: 264693 | BL22: 260124 | BM22: 250166 | BN22: 353577 | BO22: 3028847
A23: 17 | B23: Batam | C23: 260 | D23: 157 | E23: 343 | F23: 191 | G23: 245 | H23: 250 | I23: 153 | J23: 149 | K23: 129 | L23: 158 | M23: 234 | N23: 313 | O23: 2582 | P23: 240 | Q23: 329 | R23: 995 | S23: 8136 | T23: 16741 | U23: 39649 | V23: 56610 | W23: 59750 | X23: 77981 | Y23: 77752 | Z23: 80216 | AA23: 144521 | AB23: 562920 | AC23: 93781 | AD23: 73090 | AE23: 97040 | AF23: 88776 | AG23: 76577 | AH23: 133616 | AI23: 94373 | AJ23: 94601 | AK23: 101470 | AL23: 79646 | AM23: 103497 | AN23: 149218 | AO23: 1185685 | AP23: 77836 | AQ23: 111758 | AR23: 104191 | AS23: 78674 | AT23: 99404 | AU23: 130714 | AV23: 100295 | AW23: 119550 | AX23: 114682 | AY23: 109864 | AZ23: 111306 | BA23: 157945 | BB23: 1316219 | BC23: 123223 | BD23: 103491 | BE23: 99412 | BF23: 99257 | BG23: 139491 | BH23: 166223 | BI23: 121487 | BJ23: 144698 | BK23: 140073 | BL23: 137435 | BM23: 125503 | BN23: 193464 | BO23: 1593757 | BP23: =SUM($BO23,$BB23,$AO23,$AB23,$O23) -> 4661163
A24: 18 | B24: Tanjung Uban | C24: 0 | D24: 0 | E24: 81 | F24: 10 | G24: 20 | H24: 20 | I24: 0 | J24: 0 | K24: 0 | L24: 0 | M24: 51 | N24: 77 | O24: 259 | P24: 88 | Q24: 31 | R24: 367 | S24: 2998 | T24: 5281 | U24: 12509 | V24: 16988 | W24: 13277 | X24: 18218 | Y24: 19932 | Z24: 16473 | AA24: 31367 | AB24: 137529 | AC24: 14957 | AD24: 11265 | AE24: 19018 | AF24: 18547 | AG24: 15001 | AH24: 26345 | AI24: 17619 | AJ24: 19237 | AK24: 20542 | AL24: 16838 | AM24: 16544 | AN24: 26205 | AO24: 222118 | AP24: 11442 | AQ24: 18432 | AR24: 20741 | AS24: 14202 | AT24: 14974 | AU24: 22829 | AV24: 16210 | AW24: 20655 | AX24: 16058 | AY24: 15916 | AZ24: 14933 | BA24: 22213 | BB24: 208605 | BC24: 15791 | BD24: 9815 | BE24: 17619 | BF24: 15254 | BG24: 20284 | BH24: 32073 | BI24: 21939 | BJ24: 24930 | BK24: 20974 | BL24: 22633 | BM24: 16867 | BN24: 35187 | BO24: 253366 | BP24: =SUM($BO24,$BB24,$AO24,$AB24,$O24) -> 821877
A25: 19 | B25: Tanjung Pinang | C25: 0 | D25: 0 | E25: 0 | F25: 0 | G25: 0 | H25: 0 | I25: 0 | J25: 0 | K25: 0 | L25: 0 | M25: 0 | N25: 154 | O25: 154 | P25: 0 | Q25: 4 | R25: 1 | S25: 660 | T25: 1141 | U25: 2758 | V25: 1965 | W25: 2801 | X25: 3716 | Y25: 3912 | Z25: 3117 | AA25: 5475 | AB25: 25550 | AC25: 4973 | AD25: 2663 | AE25: 4043 | AF25: 5324 | AG25: 3391 | AH25: 6086 | AI25: 4010 | AJ25: 4222 | AK25: 4827 | AL25: 5065 | AM25: 5912 | AN25: 7022 | AO25: 57538 | AP25: 2803 | AQ25: 5921 | AR25: 4868 | AS25: 2614 | AT25: 3904 | AU25: 6135 | AV25: 3573 | AW25: 5948 | AX25: 4898 | AY25: 4632 | AZ25: 4388 | BA25: 5788 | BB25: 55472 | BC25: 5583 | BD25: 4095 | BE25: 5218 | BF25: 4995 | BG25: 6071 | BH25: 6603 | BI25: 4620 | BJ25: 4909 | BK25: 4971 | BL25: 5285 | BM25: 4880 | BN25: 6076 | BO25: 63306 | BP25: =SUM($BO25,$BB25,$AO25,$AB25,$O25) -> 202020
A26: 20 | B26: Tanjung Balai Karimun | C26: 0 | D26: 15 | E26: 0 | F26: 0 | G26: 0 | H26: 0 | I26: 0 | J26: 0 | K26: 0 | L26: 0 | M26: 0 | N26: 0 | O26: 15 | P26: 0 | Q26: 0 | R26: 0 | S26: 0 | T26: 659 | U26: 2519 | V26: 4122 | W26: 3139 | X26: 4188 | Y26: 4085 | Z26: 3588 | AA26: 6684 | AB26: 28984 | AC26: 5814 | AD26: 4795 | AE26: 4835 | AF26: 5801 | AG26: 3590 | AH26: 4734 | AI26: 4391 | AJ26: 4173 | AK26: 4345 | AL26: 4298 | AM26: 4683 | AN26: 6634 | AO26: 58093 | AP26: 4050 | AQ26: 7747 | AR26: 5039 | AS26: 6899 | AT26: 5292 | AU26: 6436 | AV26: 5476 | AW26: 6555 | AX26: 6814 | AY26: 6770 | AZ26: 6911 | BA26: 7649 | BB26: 75638 | BC26: 8038 | BD26: 7099 | BE26: 5773 | BF26: 6137 | BG26: 9131 | BH26: 9531 | BI26: 7927 | BJ26: 8272 | BK26: 8364 | BL26: 8541 | BM26: 7938 | BN26: 10212 | BO26: 96963 | BP26: =SUM($BO26,$BB26,$AO26,$AB26,$O26) -> 259693
A27: 21 | B27: Tanjung Benoa | C27: 8 | D27: 0 | E27: 0 | F27: 0 | G27: 0 | H27: 0 | I27: 0 | J27: 0 | K27: 0 | L27: 0 | M27: 0 | N27: 0 | O27: 8 | P27: 3 | Q27: 17 | R27: 3 | S27: 20 | T27: 58 | U27: 80 | V27: 62 | W27: 32 | X27: 46 | Y27: 92 | Z27: 373 | AA27: 914 | AB27: 1700 | AC27: 1876 | AD27: 6505 | AE27: 3738 | AF27: 1229 | AG27: 21 | AH27: 71 | AI27: 81 | AJ27: 78 | AK27: 53 | AL27: 2596 | AM27: 5632 | AN27: 801 | AO27: 22681 | AP27: 853 | AQ27: 879 | AR27: 5423 | AS27: 324 | AT27: 109 | AU27: 106 | AV27: 95 | AW27: 3100 | AX27: 2061 | AY27: 5019 | AZ27: 186 | BA27: 53 | BB27: 18208 | BC27: 976 | BD27: 2219 | BE27: 6154 | BF27: 3906 | BG27: 158 | BH27: 124 | BI27: 39 | BJ27: 27 | BK27: 667 | BL27: 7 | BM27: 6857 | BN27: 6844 | BO27: 27978 | BP27: =SUM($BO27,$BB27,$AO27,$AB27,$O27) -> 70575
A28: 22 | B28: Tanjung Mas | C28: - | D28: - | E28: - | F28: - | G28: - | H28: - | I28: - | J28: - | K28: - | L28: - | M28: - | N28: - | O28: 0 | P28: - | Q28: - | R28: - | S28: - | T28: - | U28: - | V28: - | W28: - | X28: - | Y28: - | Z28: - | AA28: - | AB28: - | AC28: - | AD28: - | AE28: - | AF28: - | AG28: - | AH28: - | AI28: - | AJ28: - | AK28: - | AL28: - | AM28: - | AN28: - | AO28: - | AP28: 0 | AQ28: 0 | AR28: 0 | AS28: 0 | AT28: 0 | AU28: 0 | AV28: 0 | AW28: 0 | AX28: 0 | AY28: 0 | AZ28: 565 | BA28: 1302 | BB28: 1867 | BC28: 640 | BD28: 0 | BE28: 1129 | BF28: 535 | BG28: 0 | BH28: 619 | BI28: 0 | BJ28: 0 | BK28: 0 | BL28: 0 | BM28: 1722 | BN28: 0 | BO28: 4645 | BP28: =SUM($BO28,$BB28,$AO28,$AB28,$O28) -> 6512
A29: 23 | B29: Pintu Laut Lainnya | C29: 37399 | D29: 29128 | E29: 34893 | F29: 30717 | G29: 39455 | H29: 29659 | I29: 35358 | J29: 33348 | K29: 33268 | L29: 38087 | M29: 32456 | N29: 38686 | O29: 412454 | P29: 58111 | Q29: 51158 | R29: 58991 | S29: 57271 | T29: 81839 | U29: 77149 | V29: 104446 | W29: 85919 | X29: 92519 | Y29: 101617 | Z29: 90127 | AA29: 111006 | AB29: 970153 | AC29: 103450 | AD29: 92745 | AE29: 107507 | AF29: 115983 | AG29: 115746 | AH29: 105187 | AI29: 104632 | AJ29: 97888 | AK29: 81533 | AL29: 77718 | AM29: 53990 | AN29: 101883 | AO29: 1158262 | AP29: 101088 | AQ29: 94981 | AR29: 111751 | AS29: 109003 | AT29: 89035 | AU29: 94945 | AV29: 86784 | AW29: 92950 | AX29: 87235 | AY29: 76419 | AZ29: 85004 | BA29: 69742 | BB29: 1098896 | BC29: 78016 | BD29: 76731 | BE29: 71092 | BF29: 70466 | BG29: 69034 | BH29: 92642 | BI29: 86587 | BJ29: 80204 | BK29: 89644 | BL29: 86223 | BM29: 86399 | BN29: 101794 | BO29: 988832 | BP29: =SUM($BO29,$BB29,$AO29,$AB29,$O29) -> 4628597
A30: C | B30: C. Pintu Darat | C30: 87117 | D30: 69378 | E30: 71810 | F30: 63512 | G30: 85673 | H30: 80681 | I30: 84563 | J30: 83427 | K30: 81955 | L30: 92170 | M30: 97927 | N30: 106603 | O30: 1004816 | P30: 63301 | Q30: 48136 | R30: 59210 | S30: 63590 | T30: 65371 | U30: 68737 | V30: 73744 | W30: 83091 | X30: 79740 | Y30: 79764 | Z30: 80910 | AA30: 100575 | AB30: 866169 | AC30: 89121 | AD30: 70924 | AE30: 78398 | AF30: 69717 | AG30: 80323 | AH30: 79276 | AI30: 76587 | AJ30: 85993 | AK30: 79938 | AL30: 84774 | AM30: 84260 | AN30: 121486 | AO30: 1000797 | AP30: 97713 | AQ30: 87359 | AR30: 107409 | AS30: 105157 | AT30: 97059 | AU30: 115122 | AV30: 103740 | AW30: 103641 | AX30: 105607 | AY30: 115500 | AZ30: 111802 | BA30: 131073 | BB30: 1281223 | BC30: 122131 | BD30: 100835 | BE30: 108893 | BF30: 109233 | BG30: 120739 | BH30: 130352 | BI30: 137128 | BJ30: 134047 | BK30: 133699 | BL30: 134653 | BM30: 143179 | BN30: 163619 | BO30: 1538508
A31: 24 | B31: Jayapura | C31: 2 | D31: 2 | E31: 0 | F31: 3 | G31: 0 | H31: 0 | I31: 0 | J31: 0 | K31: 3 | L31: 0 | M31: 0 | N31: 3 | O31: 13 | P31: 0 | Q31: 0 | R31: 0 | S31: 20 | T31: 0 | U31: 0 | V31: 0 | W31: 0 | X31: 0 | Y31: 78 | Z31: 166 | AA31: 184 | AB31: 448 | AC31: 132 | AD31: 86 | AE31: 106 | AF31: 91 | AG31: 8251 | AH31: 9933 | AI31: 7723 | AJ31: 8335 | AK31: 8408 | AL31: 9174 | AM31: 3729 | AN31: 11445 | AO31: 67413 | AP31: 8254 | AQ31: 6903 | AR31: 6515 | AS31: 7129 | AT31: 7305 | AU31: 8577 | AV31: 8544 | AW31: 9481 | AX31: 11649 | AY31: 10715 | AZ31: 11188 | BA31: 14613 | BB31: 110873 | BC31: 12617 | BD31: 11015 | BE31: 5943 | BF31: 9296 | BG31: 9107 | BH31: 10569 | BI31: 11553 | BJ31: 10344 | BK31: 12494 | BL31: 11274 | BM31: 11230 | BN31: 17405 | BO31: 132847 | BP31: =SUM($BO31,$BB31,$AO31,$AB31,$O31) -> 311594
A32: 25 | B32: Atambua | C32: 4 | D32: 26 | E32: 0 | F32: 3 | G32: 13 | H32: 152 | I32: 12 | J32: 12 | K32: 73 | L32: 64 | M32: 142 | N32: 184 | O32: 685 | P32: 234 | Q32: 226 | R32: 317 | S32: 737 | T32: 1203 | U32: 1792 | V32: 1149 | W32: 3120 | X32: 2672 | Y32: 2646 | Z32: 2511 | AA32: 4300 | AB32: 20907 | AC32: 2514 | AD32: 4212 | AE32: 7016 | AF32: 7322 | AG32: 6651 | AH32: 8267 | AI32: 8198 | AJ32: 11895 | AK32: 8942 | AL32: 9700 | AM32: 8838 | AN32: 12678 | AO32: 96233 | AP32: 8426 | AQ32: 7423 | AR32: 8958 | AS32: 9209 | AT32: 9670 | AU32: 11141 | AV32: 11847 | AW32: 10029 | AX32: 8384 | AY32: 13025 | AZ32: 16360 | BA32: 18751 | BB32: 133223 | BC32: 11445 | BD32: 10244 | BE32: 13058 | BF32: 14292 | BG32: 15441 | BH32: 17380 | BI32: 21031 | BJ32: 20318 | BK32: 18282 | BL32: 21420 | BM32: 20476 | BN32: 29738 | BO32: 213125 | BP32: =SUM($BO32,$BB32,$AO32,$AB32,$O32) -> 464173
A33: 26 | B33: Entikong | C33: 6 | D33: 11 | E33: 14 | F33: 2 | G33: 0 | H33: 0 | I33: 1 | J33: 0 | K33: 0 | L33: 0 | M33: 2 | N33: 10 | O33: 46 | P33: 0 | Q33: 0 | R33: 2 | S33: 254 | T33: 556 | U33: 789 | V33: 646 | W33: 745 | X33: 1360 | Y33: 1804 | Z33: 1771 | AA33: 3877 | AB33: 11804 | AC33: 2508 | AD33: 2725 | AE33: 2905 | AF33: 2929 | AG33: 2856 | AH33: 2819 | AI33: 2639 | AJ33: 3488 | AK33: 2418 | AL33: 2274 | AM33: 2364 | AN33: 4522 | AO33: 34447 | AP33: 2366 | AQ33: 4380 | AR33: 2540 | AS33: 4042 | AT33: 3737 | AU33: 2819 | AV33: 3204 | AW33: 3191 | AX33: 4256 | AY33: 3331 | AZ33: 2797 | BA33: 5017 | BB33: 41680 | BC33: 4130 | BD33: 3482 | BE33: 2923 | BF33: 2719 | BG33: 5321 | BH33: 4734 | BI33: 3534 | BJ33: 3803 | BK33: 4446 | BL33: 3135 | BM33: 2880 | BN33: 5269 | BO33: 46376 | BP33: =SUM($BO33,$BB33,$AO33,$AB33,$O33) -> 134353
A34: 27 | B34: Aruk | C34: 3 | D34: 2 | E34: 13 | F34: 1 | G34: 1 | H34: 0 | I34: 1 | J34: 0 | K34: 0 | L34: 1 | M34: 3 | N34: 2 | O34: 27 | P34: 0 | Q34: 0 | R34: 0 | S34: 218 | T34: 622 | U34: 969 | V34: 1792 | W34: 1149 | X34: 1692 | Y34: 2116 | Z34: 1197 | AA34: 3020 | AB34: 12775 | AC34: 2542 | AD34: 2503 | AE34: 2169 | AF34: 3592 | AG34: 2057 | AH34: 2755 | AI34: 1832 | AJ34: 2653 | AK34: 1878 | AL34: 1721 | AM34: 1790 | AN34: 3605 | AO34: 29097 | AP34: 1733 | AQ34: 4433 | AR34: 2400 | AS34: 3521 | AT34: 2225 | AU34: 2878 | AV34: 2926 | AW34: 2819 | AX34: 3680 | AY34: 2376 | AZ34: 2208 | BA34: 3787 | BB34: 34986 | BC34: 3870 | BD34: 3482 | BE34: 3338 | BF34: 2583 | BG34: 3746 | BH34: 4858 | BI34: 2692 | BJ34: 2973 | BK34: 3921 | BL34: 3097 | BM34: 2391 | BN34: 4038 | BO34: 40989 | BP34: =SUM($BO34,$BB34,$AO34,$AB34,$O34) -> 117874
A35: 28 | B35: Nanga Badau | C35: 0 | D35: 0 | E35: 0 | F35: 0 | G35: 0 | H35: 0 | I35: 0 | J35: 0 | K35: 0 | L35: 0 | M35: 0 | N35: 0 | O35: 0 | P35: 0 | Q35: 0 | R35: 0 | S35: 0 | T35: 0 | U35: 0 | V35: 15 | W35: 318 | X35: 425 | Y35: 347 | Z35: 291 | AA35: 1153 | AB35: 2549 | AC35: 718 | AD35: 615 | AE35: 669 | AF35: 735 | AG35: 1324 | AH35: 1045 | AI35: 727 | AJ35: 628 | AK35: 680 | AL35: 674 | AM35: 724 | AN35: 1363 | AO35: 9902 | AP35: 687 | AQ35: 950 | AR35: 965 | AS35: 486 | AT35: 833 | AU35: 1028 | AV35: 940 | AW35: 892 | AX35: 1116 | AY35: 742 | AZ35: 732 | BA35: 1493 | BB35: 10864 | BC35: 1143 | BD35: 935 | BE35: 974 | BF35: 798 | BG35: 1716 | BH35: 1259 | BI35: 1047 | BJ35: 1116 | BK35: 991 | BL35: 918 | BM35: 816 | BN35: 1782 | BO35: 13495 | BP35: =SUM($BO35,$BB35,$AO35,$AB35,$O35) -> 36810
A36: 29 | B36: Pintu Darat Lainnya | C36: 87102 | D36: 69337 | E36: 71783 | F36: 63503 | G36: 85659 | H36: 80529 | I36: 84549 | J36: 83415 | K36: 81879 | L36: 92105 | M36: 97780 | N36: 106404 | O36: 1004045 | P36: 63067 | Q36: 47910 | R36: 58891 | S36: 62361 | T36: 62990 | U36: 65187 | V36: 70142 | W36: 77759 | X36: 73591 | Y36: 72773 | Z36: 74974 | AA36: 88041 | AB36: 817686 | AC36: 80707 | AD36: 60783 | AE36: 65533 | AF36: 55048 | AG36: 59184 | AH36: 54457 | AI36: 55468 | AJ36: 58994 | AK36: 57612 | AL36: 61231 | AM36: 66815 | AN36: 87873 | AO36: 763705 | AP36: 76247 | AQ36: 63270 | AR36: 86031 | AS36: 80770 | AT36: 73289 | AU36: 88679 | AV36: 76279 | AW36: 77229 | AX36: 76522 | AY36: 85311 | AZ36: 78517 | BA36: 87412 | BB36: 949597 | BC36: 88926 | BD36: 71677 | BE36: 82657 | BF36: 79545 | BG36: 85408 | BH36: 91552 | BI36: 97271 | BJ36: 95493 | BK36: 93565 | BL36: 94809 | BM36: 105386 | BN36: 105387 | BO36: 1091676 | BP36: =SUM($BO36,$BB36,$AO36,$AB36,$O36) -> 4626709
A37: D | B37: Jumlah (A+B+C) | C37: 126515 | D37: 105788 | E37: 119979 | F37: 112756 | G37: 139433 | H37: 126844 | I37: 127249 | J37: 118533 | K37: 120100 | L37: 146137 | M37: 150577 | N37: 163619 | O37: 1557530 | P37: 136298 | Q37: 117509 | R37: 158629 | S37: 230076 | T37: 354920 | U37: 483883 | V37: 645121 | W37: 670509 | X37: 700606 | Y37: 734228 | Z37: 704783 | AA37: 952469 | AB37: 5889031 | AC37: 798469 | AD37: 749436 | AE37: 869244 | AF37: 865811 | AG37: 953714 | AH37: 1062791 | AI37: 1121189 | AJ37: 1132638 | AK37: 1070245 | AL37: 978519 | AM37: 931227 | AN37: 1144542 | AO37: 11677825 | AP37: 927746 | AQ37: 1062149 | AR37: 1041861 | AS37: 1066958 | AT37: 1145499 | AU37: 1197941 | AV37: 1310756 | AW37: 1339946 | AX37: 1279258 | AY37: 1193867 | AZ37: 1092067 | BA37: 1228630 | BB37: 13886678 | BC37: 1156012 | BD37: 1022894 | BE37: 984769 | BF37: 1164539 | BG37: 1306000 | BH37: 1417096 | BI37: 1481346 | BJ37: 1505220 | BK37: 1394910 | BL37: 1348993 | BM37: 1199007 | BN37: 1405860 | BO37: 15386646
B38: Lainnya | C38: - | D38: - | E38: - | F38: - | G38: - | H38: - | I38: - | J38: - | K38: - | L38: - | M38: - | N38: - | O38: - | P38: - | Q38: - | R38: - | S38: - | T38: - | U38: - | V38: - | W38: - | X38: - | Y38: - | Z38: - | AA38: - | AB38: - | AC38: - | AD38: - | AE38: - | AF38: - | AG38: - | AH38: - | AI38: - | AJ38: - | AK38: - | AL38: - | AM38: - | AN38: - | AO38: - | AP38: - | AQ38: - | AR38: - | AS38: - | AT38: - | AU38: - | AV38: - | AW38: - | AX38: - | AY38: - | AZ38: - | BA38: 0 | BB38: 0 | BC38: 0 | BD38: 0 | BE38: 0 | BF38: 0 | BG38: 0 | BH38: 0 | BI38: 0 | BJ38: 0 | BK38: 0 | BL38: 0 | BM38: 0 | BN38: 0 | BO38: 0
A39: E | B39: Total | C39: 126515 | D39: 105788 | E39: 119979 | F39: 112756 | G39: 139433 | H39: 126844 | I39: 127249 | J39: 118533 | K39: 120100 | L39: 146137 | M39: 150577 | N39: 163619 | O39: 1557530 | P39: 136298 | Q39: 117509 | R39: 158629 | S39: 230076 | T39: 354920 | U39: 483883 | V39: 645121 | W39: 670509 | X39: 700606 | Y39: 734228 | Z39: 704783 | AA39: 952469 | AB39: 5889031 | AC39: 798469 | AD39: 749436 | AE39: 869244 | AF39: 865811 | AG39: 953714 | AH39: 1062791 | AI39: 1121189 | AJ39: 1132638 | AK39: 1070245 | AL39: 978519 | AM39: 931227 | AN39: 1144542 | AO39: 11677825 | AP39: 927746 | AQ39: 1062149 | AR39: 1041861 | AS39: 1066958 | AT39: 1145499 | AU39: 1197941 | AV39: 1310756 | AW39: 1339946 | AX39: 1279258 | AY39: 1193867 | AZ39: 1092067 | BA39: 1228630 | BB39: 13886678 | BC39: 1156012 | BD39: 1022894 | BE39: 984769 | BF39: 1164539 | BG39: 1306000 | BH39: 1417096 | BI39: 1481346 | BJ39: 1505220 | BK39: 1394910 | BL39: 1348993 | BM39: 1199007 | BN39: 1405860 | BO39: 15386646
B41: Kebangsaan | C41: Jumlah Kunjungan Wisatawan Mancanegara per bulan ke Indonesia Menurut Kebangsaan (Kunjungan)
C43: 2021 | P43: 2022 | AC43: 2023 | AP43: 2024 | BC43: 2025
C44: Januari | D44: Februari | E44: Maret | F44: April | G44: Mei | H44: Juni | I44: Juli | J44: Agustus | K44: September | L44: Oktober | M44: November | N44: Desember | O44: Tahunan | P44: Januari | Q44: Februari | R44: Maret | S44: April | T44: Mei | U44: Juni | V44: Juli | W44: Agustus | X44: September | Y44: Oktober | Z44: November | AA44: Desember | AB44: Tahunan | AC44: Januari | AD44: Februari | AE44: Maret | AF44: April | AG44: Mei | AH44: Juni | AI44: Juli | AJ44: Agustus | AK44: September | AL44: Oktober | AM44: November | AN44: Desember | AO44: Tahunan | AP44: Januari | AQ44: Februari | AR44: Maret | AS44: April | AT44: Mei | AU44: Juni | AV44: Juli | AW44: Agustus | AX44: September | AY44: Oktober | AZ44: November | BA44: Desember | BB44: Tahunan | BC44: Januari | BD44: Februari | BE44: Maret | BF44: April | BG44: Mei | BH44: Juni | BI44: Juli | BJ44: Agustus | BK44: September | BL44: Oktober | BM44: November | BN44: Desember | BO44: Tahunan | BP44: Total
A45: 1 | B45: Malaysia | C45: 44001 | D45: 34425 | E45: 37095 | F45: 35871 | G45: 45322 | H45: 34345 | I45: 41913 | J45: 37530 | K45: 37946 | L45: 44113 | M45: 39434 | N45: 48728 | O45: 480723 | P45: 55214 | Q45: 46894 | R45: 54006 | S45: 63079 | T45: 95099 | U45: 95277 | V45: 124849 | W45: 112314 | X45: 124445 | Y45: 131169 | Z45: 121035 | AA45: 189193 | AB45: 1212574 | AC45: 140071 | AD45: 150078 | AE45: 152447 | AF45: 147248 | AG45: 169185 | AH45: 168759 | AI45: 154967 | AJ45: 174788 | AK45: 152210 | AL45: 138597 | AM45: 141746 | AN45: 211146 | AO45: 1901242 | AP45: 155213 | AQ45: 218057 | AR45: 160269 | AS45: 170644 | AT45: 200070 | AU45: 183696 | AV45: 177711 | AW45: 188752 | AX45: 234466 | AY45: 194099 | AZ45: 174265 | BA45: 213314 | BB45: 2270556 | BC45: 221474 | BD45: 214605 | BE45: 159895 | BF45: 170018 | BG45: 238497 | BH45: 236417 | BI45: 212113 | BJ45: 229726 | BK45: 272421 | BL45: 234384 | BM45: 207037 | BN45: 243162 | BO45: 2639749 | BP45: =SUM($BO45,$BB45,$AO45,$AB45,$O45) -> 8504844
A46: 2 | B46: Singapore | C46: 2107 | D46: 1864 | E46: 2396 | F46: 2541 | G46: 2293 | H46: 1049 | I46: 980 | J46: 946 | K46: 729 | L46: 1142 | M46: 1462 | N46: 1195 | O46: 18704 | P46: 2199 | Q46: 2237 | R46: 5335 | S46: 15106 | T46: 27671 | U46: 57218 | V46: 67758 | W46: 70621 | X46: 95549 | Y46: 94172 | Z46: 107705 | AA46: 191226 | AB46: 736797 | AC46: 107735 | AD46: 84358 | AE46: 124340 | AF46: 97280 | AG46: 100729 | AH46: 174443 | AI46: 109847 | AJ46: 105456 | AK46: 114713 | AL46: 89770 | AM46: 118005 | AN46: 187771 | AO46: 1414447 | AP46: 87248 | AQ46: 114301 | AR46: 120040 | AS46: 81225 | AT46: 111021 | AU46: 157085 | AV46: 102322 | AW46: 125512 | AX46: 106963 | AY46: 106307 | AZ46: 120449 | BA46: 172825 | BB46: 1405298 | BC46: 110484 | BD46: 89757 | BE46: 100883 | BF46: 97506 | BG46: 126391 | BH46: 183748 | BI46: 114224 | BJ46: 129864 | BK46: 119237 | BL46: 123578 | BM46: 126254 | BN46: 204512 | BO46: 1526438 | BP46: =SUM($BO46,$BB46,$AO46,$AB46,$O46) -> 5101684
...

Sheet Tabel Bantuan
A1: Jumlah Kunjungan Wisatawan Mancanegara per bulan ke Indonesia Menurut Pintu Masuk 2021-2025 | J1: Jumlah Kunjungan Wisatawan Mancanegara per bulan ke Indonesia Menurut Kebangsaan (Kunjungan)
A2: Indeks | B2: 1 | J2: Indeks | K2: 2
A3: Pintu Masuk | B3: =IF(MATCH('Tabel Bantuan'!B4,Data!B6:B21,0),"Udara",IF(MATCH('Tabel Bantuan'!B4,Data!B23:B29,0),"Laut","Darat")) -> Udara | F3: Total Wisatawan | J3: Benua | K3: =VLOOKUP('Tabel Bantuan'!K2,'Tabel Bantuan'!I11:J17,2,FALSE) -> ASIA (Excl. Asean) | M3: Tota Wisatawan | P3: Total Kebangsaan
A4: Nama Pintu | B4: =VLOOKUP('Tabel Bantuan'!B2,Data!A5:B36,2,FALSE) -> Ngurah Rai | F4: =SUM(B8:D12) -> 48397710 | M4: =SUM(Data!O289,Data!AB289,Data!AO289,Data!BB289,Data!BO289) -> 48397710 | P4: =COUNTA(Data!B45:B288)-COUNTA(J11:J17) -> 237
J5: Indeks | K5: 1
A6: Total Kunjungan Pintu Masuk Per-Tahun (2021-2025) | F6: Pintu Masuk Paling Sering Digunakan | J6: Kebangsaan | K6: =VLOOKUP('Tabel Bantuan'!K5,Data!A45:B287,2,FALSE) -> Malaysia
F7: =INDEX(B16:D16,MATCH(MAX(B22:D22),B22:D22,0)) -> Pintu Udara
A8: 2021 | B8: =Data!O39 -> 1557530 | J8: Total Wisatawan Berdasarkan Benua (2021-2025) | P8: Jumlah
A9: 2022 | B9: =Data!AB39 -> 5889031 | F9: Total Kunjungan Berdasarkan Pintu Masuk
A10: 2023 | B10: =Data!AO39 -> 11677825 | J10: Tahun | K10: 2021 | L10: 2022 | M10: 2023 | N10: 2024 | O10: 2025
A11: 2024 | B11: =Data!BB39 -> 13886678 | F11: Tahun | G11: =B32 -> 2025 | I11: 1 | J11: ASEAN | K11: =Data!O56 -> 1347714 | L11: =Data!AB56 -> 3111878 | M11: =Data!AO56 -> 4977336 | N11: =Data!BB56 -> 5572869 | O11: =Data!BO56 -> 6356941 | P11: =SUM($K11:$O11) -> 21366738
A12: 2025 | B12: =Data!BO39 -> 15386646 | I12: 2 | J12: ASIA (Excl. Asean) | K12: =Data!O80 -> 85353 | L12: =Data!AB80 -> 722608 | M12: =Data!AO80 -> 2254077 | N12: =Data!BB80 -> 3069060 | O12: =Data!BO80 -> 3498891 | P12: =SUM($K12:$O12) -> 9629989
F13: Pintu Masuk | G13: Jumlah | I13: 3 | J13: MIDDLE EAST | K13: =Data!O97 -> 5639 | L13: =Data!AB97 -> 81834 | M13: =Data!AO97 -> 181558 | N13: =Data!BB97 -> 224428 | O13: =Data!BO97 -> 260098 | P13: =SUM($K13:$O13) -> 753557 | S13: Total Wisatawan Berdasarkan Benua
A14: Total Kunjungan Berdasarkan Pintu Masuk Per-Tahun (2021-2025) | F14: Pintu Udara | G14: =VLOOKUP($B$32,$A$16:$D$21,2,FALSE) -> 10819291 | I14: 4 | J14: EUROPE | K14: =Data!O156 -> 55906 | L14: =Data!AB156 -> 960410 | M14: =Data!AO156 -> 2000559 | N14: =Data!BB156 -> 2370743 | O14: =Data!BO156 -> 2456951 | P14: =SUM($K14:$O14) -> 7844569 | S14: Benua | T14: ='Tabel Bantuan'!K3 -> ASIA (Excl. Asean)
F15: Pintu Laut | G15: =VLOOKUP($B$32,$A$16:$D$21,3,FALSE) -> 3028847 | I15: 5 | J15: AMERICA | K15: =Data!O204 -> 25073 | L15: =Data!AB204 -> 260095 | M15: =Data!AO204 -> 566883 | N15: =Data!BB204 -> 603300 | O15: =Data!BO204 -> 615801 | P15: =SUM($K15:$O15) -> 2071152
A16: Tahun | B16: Pintu Udara | C16: Pintu Laut | D16: Pintu Darat | F16: Pintu Darat | G16: =VLOOKUP($B$32,$A$16:$D$21,4,FALSE) -> 1538508 | I16: 6 | J16: OCEANIA | K16: =Data!O227 -> 35504 | L16: =Data!AB227 -> 722524 | M16: =Data!AO227 -> 1625760 | N16: =Data!BB227 -> 1957643 | O16: =Data!BO227 -> 2094440 | P16: =SUM($K16:$O16) -> 6435871 | S16: Tahun | T16: Jumlah Wisman
A17: 2021 | B17: =Data!O5 -> 137242 | C17: =Data!O22 -> 415472 | D17: =Data!O30 -> 1004816 | E17: =SUM($B17:$D17) -> 1557530 | F17: Total | G17: =SUM('Tabel Bantuan'!G14:H16) -> 15386646 | I17: 7 | J17: AFRICA | K17: =Data!O288 -> 2341 | L17: =Data!AB288 -> 29682 | M17: =Data!AO288 -> 71652 | N17: =Data!BB288 -> 88635 | O17: =Data!BO288 -> 103524 | P17: =SUM($K17:$O17) -> 295834 | S17: 2021 | T17: =VLOOKUP('Tabel Bantuan'!$K$3,'Tabel Bantuan'!$J$11:$O$17,$I$11+1,FALSE) -> 85353
A18: 2022 | B18: =Data!AB5 -> 3296026 | C18: =Data!AB22 -> 1726836 | D18: =Data!AB30 -> 866169 | E18: =SUM($B18:$D18) -> 5889031 | S18: 2022 | T18: =VLOOKUP('Tabel Bantuan'!$K$3,'Tabel Bantuan'!$J$11:$O$17,$I$11+2,FALSE) -> 722608
A19: 2023 | B19: =Data!AO5 -> 7972651 | C19: =Data!AO22 -> 2704377 | D19: =Data!AO30 -> 1000797 | E19: =SUM($B19:$D19) -> 11677825 | F19: Total Wisatawan Berdasarkan Benua | J19: Negara Penyumbang Wisatawan Mancanegara Terbanyak | S19: 2023 | T19: =VLOOKUP('Tabel Bantuan'!$K$3,'Tabel Bantuan'!$J$11:$O$17,$I$11+3,FALSE) -> 2254077
A20: 2024 | B20: =Data!BB5 -> 9830550 | C20: =Data!BB22 -> 2774905 | D20: =Data!BB30 -> 1281223 | E20: =SUM($B20:$D20) -> 13886678 | F20: Tahun | G20: =B32 -> 2025 | J20: =INDEX(Data!B45:B287,MATCH(MAX(Data!BP45:BP287),Data!BP45:BP287,0)) -> Malaysia | S20: 2024 | T20: =VLOOKUP('Tabel Bantuan'!$K$3,'Tabel Bantuan'!$J$11:$O$17,$I$11+4,FALSE) -> 3069060
A21: 2025 | B21: =Data!BO5 -> 10819291 | C21: =Data!BO22 -> 3028847 | D21: =Data!BO30 -> 1538508 | E21: =SUM($B21:$D21) -> 15386646 | S21: 2025 | T21: =VLOOKUP('Tabel Bantuan'!$K$3,'Tabel Bantuan'!$J$11:$O$17,$I$11+5,FALSE) -> 3498891
A22: Total | B22: =SUM(B$17:B$21) -> 32055760 | C22: =SUM(C$17:C$21) -> 10650437 | D22: =SUM(D$17:D$21) -> 5691513 | E22: =SUM($B22:$D22) -> 48397710 | F22: Benua | G22: Jumlah | J22: Benua Penyumbang Wisatawan Mancanegara Terbanyak
F23: ASEAN | G23: =HLOOKUP($B$32,$J$10:$O$17,2,FALSE) -> 6356941 | J23: =INDEX('Tabel Bantuan'!J11:J17,MATCH(MAX('Tabel Bantuan'!P11:P17),'Tabel Bantuan'!P11:P17,0)) -> ASEAN | S23: Total Wisatawan Berdasarkan Benua
A24: No | B24: Tahun | F24: ASIA (Excl. Asean) | G24: =HLOOKUP($B$32,$J$10:$O$17,3,FALSE) -> 3498891 | S24: =SUM('Tabel Bantuan'!T17:U21) -> 9629989
A25: 1 | B25: 2021 | F25: MIDDLE EAST | G25: =HLOOKUP($B$32,$J$10:$O$17,4,FALSE) -> 260098 | J25: 10 Negara dengan kunjungan terbanyak
A26: 2 | B26: 2022 | F26: EUROPE | G26: =HLOOKUP($B$32,$J$10:$O$17,5,FALSE) -> 2456951 | J26: Negara | K26: Wisman
A27: 3 | B27: 2023 | F27: AMERICA | G27: =HLOOKUP($B$32,$J$10:$O$17,6,FALSE) -> 615801 | J27: {=INDEX(Data!B45:B287,MATCH('Tabel Bantuan'!K27:K36,'Tabel Bantuan'!K27:K36,0))} -> Malaysia | K27: {=_xlfn.TAKE(_xlfn._xlws.SORT(Data!BP45:BP287,1,-1),10)} -> 8504844
A28: 4 | B28: 2024 | F28: OCEANIA | G28: =HLOOKUP($B$32,$J$10:$O$17,7,FALSE) -> 2094440 | J28: Singapore | K28: 5515700
A29: 5 | B29: 2025 | F29: AFRICA | G29: =HLOOKUP($B$32,$J$10:$O$17,8,FALSE) -> 103524 | J29: Timor Leste | K29: 5101684
J30: Indonesia | K30: 4047181
A31: Indeks | B31: 5 | F31: Nama Pintu Masuk Paling Banyak Digunakan | J31: Philippines | K31: 3553623
A32: Tahun | B32: =VLOOKUP(B31,A25:B29,2,FALSE) -> 2025 | F32: =INDEX(Data!B6:B36,MATCH(MAX(Data!BP6:BP36),Data!BP6:BP36,0)) -> Ngurah Rai | J32: Thailand | K32: 2339620
J33: Vietnam | K33: 1845963
F34: Jalur Pintu Masuk yang Banyak Digunakan | J34: Myanmar/Burma | K34: 1431034
F35: =INDEX('Tabel Bantuan'!F14:F16, MATCH(MAX('Tabel Bantuan'!G14:G16), 'Tabel Bantuan'!G14:G16, 0)) -> Pintu Udara | J35: Brunei Darussalam | K35: 1411740
J36: Kamboja | K36: 1315975
A46: Pertumbuhan Pertahun
A47: =B32 -> 2025 | B47: =VLOOKUP(B32,A17:E21,5,FALSE) -> 15386646
A48: =A47-1 -> 2024 | B48: =VLOOKUP((B32-1),A17:E21,5,FALSE) -> 13886678
A49: Pertumbuhan | B49: =('Tabel Bantuan'!B47-'Tabel Bantuan'!B48)/'Tabel Bantuan'!B48 -> 0.10801489
...

Sheet Dashboard
B2: Dashboard Kinerja Pariwisata Nasional: Arus Wisatawan Mancanegara (2021-2025)
I5: Total Negara (Negara)
I6: =COUNTA(Data!B45:B288)-COUNTA(J11:J17) -> 244
I9: Total Wisatawan (Orang)
I10: =SUM(Data!O289,Data!AB289,Data!AO289,Data!BB289,Data!BO289) -> 48397710
I13: Nama Pintu Masuk Paling Sering Digunakan
I15: =INDEX(Data!B6:B36,MATCH(MAX(Data!BP6:BP36),Data!BP6:BP36,0)) -> Ngurah Rai
B17: Dinamika Tren Tahunan Wisatawan Mancanegara (2021-2025)
J19: Total Wisatawan Mancanegara (Orang)
J21: =SUM('Tabel Bantuan'!G14:H16) -> 15386646
J25: Pertumbuhan Tahunan
J27: =IF('Tabel Bantuan'!B49>0, "Naik " & TEXT('Tabel Bantuan'!B49, "0,0%"), IF('Tabel Bantuan'!B49<0, "Turun " & TEXT(ABS('Tabel Bantuan'!B49), "0,0%"), "Tetap")) -> Naik 10,8%

Sheet Penjelasan
A1: Dashboard Kinerja Pariwisata Nasional: Arus Wisatawan Mancanegara (2021-2025)
A2: 1.Data yang Digunakan Dashboard ini dibangun menggunakan dua sumber data utama dari periode 2021 hingga 2025 yang saling melengkapi untuk memberikan gambaran menyeluruh mengenai sektor pariwisata nasional. Data pertama adalah "Jumlah Kunjungan Wisatawan Mancanegara per bulan ke Indonesia Menurut Pintu Masuk 2021-2025 (Kunjungan)", yang menyajikan rincian volume kedatangan wisatawan setiap bulannya di tiap tahun. Data ini sangat mendalam karena mengklasifikasikan kunjungan berdasarkan kategori pintu masuk, yaitu Pintu Udara, Pintu Laut, dan Pintu Darat, lengkap dengan nama-nama titik masuk spesifik (seperti Bandara Ngurah Rai) serta kategori "Lainnya" untuk mencakup titik-titik masuk kecil yang tidak disebutkan satu per satu secara eksplisit. Data kedua adalah "Jumlah Kunjungan Wisatawan Mancanegara per bulan ke Indonesia Menurut Kebangsaan (Kunjungan)" yang juga menyajikan data bulanan selama lima tahun terakhir. Data ini memuat informasi mengenai seluruh kebangsaan wisatawan mancanegara yang berkunjung ke Indonesia, yang kemudian dikelompokkan berdasarkan Region atau Kawasan, seperti ASEAN, Asia (Excl. ASEAN), Europe, America, Oceania, Middle East, hingga Africa. 2. Tujuan Dashboard: Dashboard ini berfungsi sebagai alat pemantauan kinerja sektor pariwisata nasional, khusus berfokus pada Arus Wisatawan Mancanegara (Wisman) yang masuk ke wilayah Indonesia selama periode 5 tahun, yaitu tahun 2021 hingga 2025. Dashboard ini dibagi menjadi dua bagian utama, bagian atas (tema biru) menampilkan ringkasan total atau akumulasi data selama 5 tahun penuh (2021-2025).Bagian Bawah (Tema Hijau) menampilkan dinamika atau tren yang bisa difilter per tahun (interaktif). Pada gambar ini, data sedang memfilter khusus kondisi di tahun 2025. 3. Penjelasan - Bagian Atas (Static Dashboard) Bagian ini memberikan pandangan luas mengenai apa yang terjadi selama 5 tahun terakhir. Total Negara (244 Negara): Selama periode 2021-2025, Indonesia berhasil menarik wisatawan yang berasal dari 244 negara yang berbeda. Ini menunjukkan jangkauan pariwisata Indonesia yang sangat luas di skala global. Total Wisatawan (48.397.710 Orang): Ini adalah angka akumulasi. Selama 5 tahun tersebut, total ada lebih dari 48,3 juta kunjungan wisatawan mancanegara. Pintu Masuk Paling Sering Digunakan (Ngurah Rai): Bandara Internasional I Gusti Ngurah Rai di Bali menjadi gerbang utama dan paling sibuk yang menerima kedatangan wisman selama 5 tahun terakhir. Grafik Batang (10 Negara Penyumbang Wisatawan Terbanyak): Grafik ini menunjukkan negara apa yang sering melakukan wisata ke Indonesia. Malaysia menduduki peringkat pertama dengan jumlah yang sangat signifikan (mencapai lebih dari 8 juta kunjungan), disusul oleh Singapura dan Timor Leste. Menariknya, 10 besar negara ini didominasi oleh negara-negara tetangga di kawasan Asia Tenggara (ASEAN). (Catatan Analitis: Di grafik ini terdapat "Indonesia" sebagai salah satu penyumbang. Dalam konteks data BPS/Pariwisata, ini biasanya merujuk pada WNI yang berdomisili di luar negeri atau pekerja migran yang kembali, yang dalam pencatatan tertentu masuk ke dalam arus lalu lintas internasional). - Bagian Bawah (Dynamic Dashboard) Bagian ini terdapat menu slicer (kotak pilihan tahun di sebelah kiri) yang saat ini sedang diklik pada angka 2025. Artinya, semua data di area berwarna hijau ini hanya merepresentasikan performa di tahun 2025 saja. Tahun 2021: Titik Awal (Baseline) Total Wisatawan: 1.557.530 orang. Ini adalah angka terendah dalam periode 5 tahun ini (sangat wajar mengingat pada tahun ini dunia masih sangat terdampak pembatasan pandemi global). Pertumbuhan Tahunan: Ditampilkan #N/A (Not Available) karena 2021 adalah tahun pertama dalam rentang data dashboard ini, sehingga tidak ada data tahun 2020 untuk dibandingkan. Kawasan Paling Dominan: Hampir seluruh wisatawan yang masuk hanya berasal dari kawasan ASEAN (sedikit di atas angka 1 juta). Wisatawan dari benua lain (Eropa, Amerika, Oceania) nyaris tidak ada atau sangat minim. Jalur Pintu Masuk: Pintu Udara (hijau tua) tetap paling banyak, tapi proporsi Pintu Laut (hijau muda) terlihat cukup lumayan dibandingkan tahun-tahun setelahnya. Tahun 2022: Fase Kebangkitan Luar Biasa (Rebound) Total Wisatawan: Melesat tajam menjadi 5.889.031 orang. Pertumbuhan Tahunan: Meroket Naik 278,1%. Ini adalah persentase pertumbuhan tertinggi selama 5 tahun. Menandakan perbatasan negara sudah mulai dibuka secara masif. Kawasan Paling Dominan: ASEAN ikut melonjak hingga menyentuh angka 3 juta kunjungan. Wisatawan dari Asia (di luar ASEAN) dan Eropa grafiknya mulai terlihat naik secara signifikan. Jalur Pintu Masuk: Dominasi Pintu Udara (bandara) mulai membesar dan "memakan" proporsi pie chart Pintu Laut dan Darat, menandakan penerbangan internasional sudah kembali beroperasi normal. Tahun 2023: Fase Akselerasi (Percepatan) Total Wisatawan: Berhasil menembus dua digit, yaitu 11.677.825 orang. Pertumbuhan Tahunan: Masih sangat tinggi di angka Naik 98,3% (hampir dua kali lipat dari tahun 2022). Kawasan Paling Dominan: Angkanya semakin merata. ASEAN menyentuh hampir 5 juta orang. Kawasan Asia (di luar ASEAN), Eropa, dan Oceania kini secara konsisten menyumbang angka di atas 1,5 hingga 2 juta kunjungan. Jalur Pintu Masuk: Potongan pie chart untuk Pintu Udara (hijau tua) semakin mendominasi secara absolut. Tahun 2024: Fase Pertumbuhan Stabil Total Wisatawan: Terus bertumbuh menjadi 13.886.678 orang. Pertumbuhan Tahunan: Angkanya melandai menjadi Naik 18,9%. Penurunan persentase ini adalah hal yang sangat normal dan sehat dalam statistik. Karena angka dasarnya (tahun 2023) sudah sangat besar, pertumbuhan tidak lagi ratusan persen, melainkan masuk ke fase stabil. Kawasan Paling Dominan: Seluruh metrik kawasan menunjukkan grafik yang naik. ASEAN melewati angka 5,5 juta, sementara Eropa dan Oceania bersaing ketat di angka sekitar 2 juta kunjungan. Tahun 2025: Puncak Pemulihan Total Wisatawan: Mencapai angka tertinggi selama periode 5 tahun, yaitu 15.386.646 orang. Pertumbuhan Tahunan: Stabil di angka Naik 10,8%. Kawasan Paling Dominan: ASEAN kokoh sebagai raja dengan lebih dari 6 juta kunjungan. Kawasan Asia (di luar ASEAN) berada di posisi kedua (sekitar 3,5 juta), disusul Eropa dan Oceania. Jalur Pintu Masuk: Pintu Udara menjadi gerbang mutlak penyokong pariwisata nasional, menyisakan porsi yang jauh lebih kecil untuk Pintu Laut dan Darat. 4. Kesimpulan / Insight dari Dashboard Pariwisata Indonesia selama 2021-2025 sangat bergantung pada pasar regional, khususnya negara-negara ASEAN seperti Malaysia dan Singapura. Mayoritas wisatawan masuk melalui jalur udara dengan Bali (Ngurah Rai) sebagai primadona utama. Kabar baiknya, tren pariwisata kita bergerak ke arah yang positif, dibuktikan dengan pertumbuhan kunjungan sebesar 10,8% pada tahun 2025 yang berhasil menembus angka 15,3 juta kunjungan
